--- Logging error in Loguru Handler #0 ---
Record was: {'elapsed': datetime.timedelta(seconds=1, microseconds=645080), 'exception': None, 'extra': {}, 'file': (name='runner.py', path='d:\\course\\course_django\\djenv\\lib\\site-packages\\httprunner\\runner.py'), 'function': 'test_start', 'level': (name='INFO', no=20, icon='ℹ️'), 'line': 450, 'message': 'Start to run testcase: case004, TestCase ID: d01fc0fc-0d37-49a3-8434-dc6a2bc15ff2', 'module': 'runner', 'name': 'httprunner.runner', 'process': (id=20516, name='MainProcess'), 'thread': (id=24788, name='MainThread'), 'time': datetime(2021, 11, 10, 16, 54, 33, 138629, tzinfo=datetime.timezone(datetime.timedelta(seconds=28800), '中国标准时间'))}
Traceback (most recent call last):
  File "d:\course\course_django\djenv\lib\site-packages\loguru\_handler.py", line 177, in emit
    self._sink.write(str_record)
  File "d:\course\course_django\djenv\lib\site-packages\loguru\_simple_sinks.py", line 26, in write
    self._stream.write(message)
  File "d:\course\course_django\djenv\lib\site-packages\colorama\ansitowin32.py", line 41, in write
    self.__convertor.write(text)
  File "d:\course\course_django\djenv\lib\site-packages\colorama\ansitowin32.py", line 162, in write
    self.write_and_convert(text)
  File "d:\course\course_django\djenv\lib\site-packages\colorama\ansitowin32.py", line 187, in write_and_convert
    self.write_plain_text(text, cursor, start)
  File "d:\course\course_django\djenv\lib\site-packages\colorama\ansitowin32.py", line 196, in write_plain_text
    self.wrapped.flush()
OSError: [WinError 6] 句柄无效。
--- End of logging error ---
--- Logging error in Loguru Handler #0 ---
Record was: {'elapsed': datetime.timedelta(seconds=1, microseconds=662937), 'exception': None, 'extra': {}, 'file': (name='runner.py', path='d:\\course\\course_django\\djenv\\lib\\site-packages\\httprunner\\runner.py'), 'function': '__run_step', 'level': (name='INFO', no=20, icon='ℹ️'), 'line': 292, 'message': 'run step begin: step_name >>>>>>', 'module': 'runner', 'name': 'httprunner.runner', 'process': (id=20516, name='MainProcess'), 'thread': (id=24788, name='MainThread'), 'time': datetime(2021, 11, 10, 16, 54, 33, 156486, tzinfo=datetime.timezone(datetime.timedelta(seconds=28800), '中国标准时间'))}
Traceback (most recent call last):
  File "d:\course\course_django\djenv\lib\site-packages\loguru\_handler.py", line 177, in emit
    self._sink.write(str_record)
  File "d:\course\course_django\djenv\lib\site-packages\loguru\_simple_sinks.py", line 26, in write
    self._stream.write(message)
  File "d:\course\course_django\djenv\lib\site-packages\colorama\ansitowin32.py", line 41, in write
    self.__convertor.write(text)
  File "d:\course\course_django\djenv\lib\site-packages\colorama\ansitowin32.py", line 162, in write
    self.write_and_convert(text)
  File "d:\course\course_django\djenv\lib\site-packages\colorama\ansitowin32.py", line 187, in write_and_convert
    self.write_plain_text(text, cursor, start)
  File "d:\course\course_django\djenv\lib\site-packages\colorama\ansitowin32.py", line 196, in write_plain_text
    self.wrapped.flush()
OSError: [WinError 6] 句柄无效。
--- End of logging error ---
--- Logging error in Loguru Handler #0 ---
Record was: {'elapsed': datetime.timedelta(seconds=5, microseconds=683812), 'exception': None, 'extra': {}, 'file': (name='client.py', path='d:\\course\\course_django\\djenv\\lib\\site-packages\\httprunner\\client.py'), 'function': 'request', 'level': (name='WARNING', no=30, icon='⚠️'), 'line': 188, 'message': "failed to get client address info: 'NoneType' object has no attribute 'connection'", 'module': 'client', 'name': 'httprunner.client', 'process': (id=20516, name='MainProcess'), 'thread': (id=24788, name='MainThread'), 'time': datetime(2021, 11, 10, 16, 54, 37, 177361, tzinfo=datetime.timezone(datetime.timedelta(seconds=28800), '中国标准时间'))}
Traceback (most recent call last):
  File "d:\course\course_django\djenv\lib\site-packages\httprunner\client.py", line 183, in request
    client_ip, client_port = response.raw.connection.sock.getsockname()
AttributeError: 'NoneType' object has no attribute 'connection'

During handling of the above exception, another exception occurred:

Traceback (most recent call last):
  File "d:\course\course_django\djenv\lib\site-packages\loguru\_handler.py", line 177, in emit
    self._sink.write(str_record)
  File "d:\course\course_django\djenv\lib\site-packages\loguru\_simple_sinks.py", line 26, in write
    self._stream.write(message)
  File "d:\course\course_django\djenv\lib\site-packages\colorama\ansitowin32.py", line 41, in write
    self.__convertor.write(text)
  File "d:\course\course_django\djenv\lib\site-packages\colorama\ansitowin32.py", line 162, in write
    self.write_and_convert(text)
  File "d:\course\course_django\djenv\lib\site-packages\colorama\ansitowin32.py", line 187, in write_and_convert
    self.write_plain_text(text, cursor, start)
  File "d:\course\course_django\djenv\lib\site-packages\colorama\ansitowin32.py", line 196, in write_plain_text
    self.wrapped.flush()
OSError: [WinError 6] 句柄无效。
--- End of logging error ---
--- Logging error in Loguru Handler #0 ---
Record was: {'elapsed': datetime.timedelta(seconds=5, microseconds=694394), 'exception': None, 'extra': {}, 'file': (name='client.py', path='d:\\course\\course_django\\djenv\\lib\\site-packages\\httprunner\\client.py'), 'function': 'request', 'level': (name='WARNING', no=30, icon='⚠️'), 'line': 196, 'message': "failed to get server address info: 'NoneType' object has no attribute 'connection'", 'module': 'client', 'name': 'httprunner.client', 'process': (id=20516, name='MainProcess'), 'thread': (id=24788, name='MainThread'), 'time': datetime(2021, 11, 10, 16, 54, 37, 187943, tzinfo=datetime.timezone(datetime.timedelta(seconds=28800), '中国标准时间'))}
Traceback (most recent call last):
  File "d:\course\course_django\djenv\lib\site-packages\httprunner\client.py", line 191, in request
    server_ip, server_port = response.raw.connection.sock.getpeername()
AttributeError: 'NoneType' object has no attribute 'connection'

During handling of the above exception, another exception occurred:

Traceback (most recent call last):
  File "d:\course\course_django\djenv\lib\site-packages\loguru\_handler.py", line 177, in emit
    self._sink.write(str_record)
  File "d:\course\course_django\djenv\lib\site-packages\loguru\_simple_sinks.py", line 26, in write
    self._stream.write(message)
  File "d:\course\course_django\djenv\lib\site-packages\colorama\ansitowin32.py", line 41, in write
    self.__convertor.write(text)
  File "d:\course\course_django\djenv\lib\site-packages\colorama\ansitowin32.py", line 162, in write
    self.write_and_convert(text)
  File "d:\course\course_django\djenv\lib\site-packages\colorama\ansitowin32.py", line 187, in write_and_convert
    self.write_plain_text(text, cursor, start)
  File "d:\course\course_django\djenv\lib\site-packages\colorama\ansitowin32.py", line 196, in write_plain_text
    self.wrapped.flush()
OSError: [WinError 6] 句柄无效。
--- End of logging error ---
--- Logging error in Loguru Handler #0 ---
Record was: {'elapsed': datetime.timedelta(seconds=5, microseconds=696378), 'exception': None, 'extra': {}, 'file': (name='client.py', path='d:\\course\\course_django\\djenv\\lib\\site-packages\\httprunner\\client.py'), 'function': 'log_print', 'level': (name='DEBUG', no=10, icon='🐞'), 'line': 40, 'message': '\n================== request details ==================\nmethod   : GET\nurl      : http://localhost/demo/path\nheaders  : {}\ncookies  : {}\nbody     : None\n', 'module': 'client', 'name': 'httprunner.client', 'process': (id=20516, name='MainProcess'), 'thread': (id=24788, name='MainThread'), 'time': datetime(2021, 11, 10, 16, 54, 37, 189927, tzinfo=datetime.timezone(datetime.timedelta(seconds=28800), '中国标准时间'))}
Traceback (most recent call last):
  File "d:\course\course_django\djenv\lib\site-packages\loguru\_handler.py", line 177, in emit
    self._sink.write(str_record)
  File "d:\course\course_django\djenv\lib\site-packages\loguru\_simple_sinks.py", line 26, in write
    self._stream.write(message)
  File "d:\course\course_django\djenv\lib\site-packages\colorama\ansitowin32.py", line 41, in write
    self.__convertor.write(text)
  File "d:\course\course_django\djenv\lib\site-packages\colorama\ansitowin32.py", line 162, in write
    self.write_and_convert(text)
  File "d:\course\course_django\djenv\lib\site-packages\colorama\ansitowin32.py", line 187, in write_and_convert
    self.write_plain_text(text, cursor, start)
  File "d:\course\course_django\djenv\lib\site-packages\colorama\ansitowin32.py", line 196, in write_plain_text
    self.wrapped.flush()
OSError: [WinError 6] 句柄无效。
--- End of logging error ---
--- Logging error in Loguru Handler #0 ---
Record was: {'elapsed': datetime.timedelta(seconds=5, microseconds=697700), 'exception': None, 'extra': {}, 'file': (name='client.py', path='d:\\course\\course_django\\djenv\\lib\\site-packages\\httprunner\\client.py'), 'function': 'log_print', 'level': (name='DEBUG', no=10, icon='🐞'), 'line': 40, 'message': '\n================== response details ==================\nstatus_code : 0\nheaders  : {}\ncookies  : {}\nencoding : None\ncontent_type : \nbody     : \n', 'module': 'client', 'name': 'httprunner.client', 'process': (id=20516, name='MainProcess'), 'thread': (id=24788, name='MainThread'), 'time': datetime(2021, 11, 10, 16, 54, 37, 191249, tzinfo=datetime.timezone(datetime.timedelta(seconds=28800), '中国标准时间'))}
Traceback (most recent call last):
  File "d:\course\course_django\djenv\lib\site-packages\loguru\_handler.py", line 177, in emit
    self._sink.write(str_record)
  File "d:\course\course_django\djenv\lib\site-packages\loguru\_simple_sinks.py", line 26, in write
    self._stream.write(message)
  File "d:\course\course_django\djenv\lib\site-packages\colorama\ansitowin32.py", line 41, in write
    self.__convertor.write(text)
  File "d:\course\course_django\djenv\lib\site-packages\colorama\ansitowin32.py", line 162, in write
    self.write_and_convert(text)
  File "d:\course\course_django\djenv\lib\site-packages\colorama\ansitowin32.py", line 187, in write_and_convert
    self.write_plain_text(text, cursor, start)
  File "d:\course\course_django\djenv\lib\site-packages\colorama\ansitowin32.py", line 196, in write_plain_text
    self.wrapped.flush()
OSError: [WinError 6] 句柄无效。
--- End of logging error ---
--- Logging error in Loguru Handler #0 ---
Record was: {'elapsed': datetime.timedelta(seconds=5, microseconds=699022), 'exception': None, 'extra': {}, 'file': (name='client.py', path='d:\\course\\course_django\\djenv\\lib\\site-packages\\httprunner\\client.py'), 'function': 'request', 'level': (name='ERROR', no=40, icon='❌'), 'line': 215, 'message': "HTTPConnectionPool(host='localhost', port=80): Max retries exceeded with url: /demo/path (Caused by NewConnectionError('<urllib3.connection.HTTPConnection object at 0x000001B30260B280>: Failed to establish a new connection: [WinError 10061] 由于目标计算机积极拒绝，无法连接。'))", 'module': 'client', 'name': 'httprunner.client', 'process': (id=20516, name='MainProcess'), 'thread': (id=24788, name='MainThread'), 'time': datetime(2021, 11, 10, 16, 54, 37, 192571, tzinfo=datetime.timezone(datetime.timedelta(seconds=28800), '中国标准时间'))}
Traceback (most recent call last):
  File "d:\course\course_django\djenv\lib\site-packages\urllib3\connection.py", line 174, in _new_conn
    conn = connection.create_connection(
  File "d:\course\course_django\djenv\lib\site-packages\urllib3\util\connection.py", line 96, in create_connection
    raise err
  File "d:\course\course_django\djenv\lib\site-packages\urllib3\util\connection.py", line 86, in create_connection
    sock.connect(sa)
ConnectionRefusedError: [WinError 10061] 由于目标计算机积极拒绝，无法连接。

During handling of the above exception, another exception occurred:

Traceback (most recent call last):
  File "d:\course\course_django\djenv\lib\site-packages\urllib3\connectionpool.py", line 699, in urlopen
    httplib_response = self._make_request(
  File "d:\course\course_django\djenv\lib\site-packages\urllib3\connectionpool.py", line 394, in _make_request
    conn.request(method, url, **httplib_request_kw)
  File "d:\course\course_django\djenv\lib\site-packages\urllib3\connection.py", line 239, in request
    super(HTTPConnection, self).request(method, url, body=body, headers=headers)
  File "C:\Users\Shone\AppData\Local\Programs\Python\Python38\lib\http\client.py", line 1252, in request
    self._send_request(method, url, body, headers, encode_chunked)
  File "C:\Users\Shone\AppData\Local\Programs\Python\Python38\lib\http\client.py", line 1298, in _send_request
    self.endheaders(body, encode_chunked=encode_chunked)
  File "C:\Users\Shone\AppData\Local\Programs\Python\Python38\lib\http\client.py", line 1247, in endheaders
    self._send_output(message_body, encode_chunked=encode_chunked)
  File "C:\Users\Shone\AppData\Local\Programs\Python\Python38\lib\http\client.py", line 1007, in _send_output
    self.send(msg)
  File "C:\Users\Shone\AppData\Local\Programs\Python\Python38\lib\http\client.py", line 947, in send
    self.connect()
  File "d:\course\course_django\djenv\lib\site-packages\urllib3\connection.py", line 205, in connect
    conn = self._new_conn()
  File "d:\course\course_django\djenv\lib\site-packages\urllib3\connection.py", line 186, in _new_conn
    raise NewConnectionError(
urllib3.exceptions.NewConnectionError: <urllib3.connection.HTTPConnection object at 0x000001B30260B280>: Failed to establish a new connection: [WinError 10061] 由于目标计算机积极拒绝，无法连接。

During handling of the above exception, another exception occurred:

Traceback (most recent call last):
  File "d:\course\course_django\djenv\lib\site-packages\requests\adapters.py", line 439, in send
    resp = conn.urlopen(
  File "d:\course\course_django\djenv\lib\site-packages\urllib3\connectionpool.py", line 755, in urlopen
    retries = retries.increment(
  File "d:\course\course_django\djenv\lib\site-packages\urllib3\util\retry.py", line 574, in increment
    raise MaxRetryError(_pool, url, error or ResponseError(cause))
urllib3.exceptions.MaxRetryError: HTTPConnectionPool(host='localhost', port=80): Max retries exceeded with url: /demo/path (Caused by NewConnectionError('<urllib3.connection.HTTPConnection object at 0x000001B30260B280>: Failed to establish a new connection: [WinError 10061] 由于目标计算机积极拒绝，无法连接。'))

During handling of the above exception, another exception occurred:

Traceback (most recent call last):
  File "d:\course\course_django\djenv\lib\site-packages\httprunner\client.py", line 213, in request
    response.raise_for_status()
  File "d:\course\course_django\djenv\lib\site-packages\httprunner\client.py", line 25, in raise_for_status
    raise self.error
  File "d:\course\course_django\djenv\lib\site-packages\httprunner\client.py", line 231, in _send_request_safe_mode
    return requests.Session.request(self, method, url, **kwargs)
  File "d:\course\course_django\djenv\lib\site-packages\requests\sessions.py", line 542, in request
    resp = self.send(prep, **send_kwargs)
  File "d:\course\course_django\djenv\lib\site-packages\requests\sessions.py", line 655, in send
    r = adapter.send(request, **kwargs)
  File "d:\course\course_django\djenv\lib\site-packages\requests\adapters.py", line 516, in send
    raise ConnectionError(e, request=request)
requests.exceptions.ConnectionError: HTTPConnectionPool(host='localhost', port=80): Max retries exceeded with url: /demo/path (Caused by NewConnectionError('<urllib3.connection.HTTPConnection object at 0x000001B30260B280>: Failed to establish a new connection: [WinError 10061] 由于目标计算机积极拒绝，无法连接。'))

During handling of the above exception, another exception occurred:

Traceback (most recent call last):
  File "d:\course\course_django\djenv\lib\site-packages\loguru\_handler.py", line 177, in emit
    self._sink.write(str_record)
  File "d:\course\course_django\djenv\lib\site-packages\loguru\_simple_sinks.py", line 26, in write
    self._stream.write(message)
  File "d:\course\course_django\djenv\lib\site-packages\colorama\ansitowin32.py", line 41, in write
    self.__convertor.write(text)
  File "d:\course\course_django\djenv\lib\site-packages\colorama\ansitowin32.py", line 162, in write
    self.write_and_convert(text)
  File "d:\course\course_django\djenv\lib\site-packages\colorama\ansitowin32.py", line 187, in write_and_convert
    self.write_plain_text(text, cursor, start)
  File "d:\course\course_django\djenv\lib\site-packages\colorama\ansitowin32.py", line 196, in write_plain_text
    self.wrapped.flush()
OSError: [WinError 6] 句柄无效。
--- End of logging error ---
--- Logging error in Loguru Handler #0 ---
Record was: {'elapsed': datetime.timedelta(seconds=5, microseconds=759866), 'exception': None, 'extra': {}, 'file': (name='runner.py', path='d:\\course\\course_django\\djenv\\lib\\site-packages\\httprunner\\runner.py'), 'function': '__run_step', 'level': (name='INFO', no=20, icon='ℹ️'), 'line': 304, 'message': 'run step end: step_name <<<<<<\n', 'module': 'runner', 'name': 'httprunner.runner', 'process': (id=20516, name='MainProcess'), 'thread': (id=24788, name='MainThread'), 'time': datetime(2021, 11, 10, 16, 54, 37, 253415, tzinfo=datetime.timezone(datetime.timedelta(seconds=28800), '中国标准时间'))}
Traceback (most recent call last):
  File "d:\course\course_django\djenv\lib\site-packages\loguru\_handler.py", line 177, in emit
    self._sink.write(str_record)
  File "d:\course\course_django\djenv\lib\site-packages\loguru\_simple_sinks.py", line 26, in write
    self._stream.write(message)
  File "d:\course\course_django\djenv\lib\site-packages\colorama\ansitowin32.py", line 41, in write
    self.__convertor.write(text)
  File "d:\course\course_django\djenv\lib\site-packages\colorama\ansitowin32.py", line 162, in write
    self.write_and_convert(text)
  File "d:\course\course_django\djenv\lib\site-packages\colorama\ansitowin32.py", line 187, in write_and_convert
    self.write_plain_text(text, cursor, start)
  File "d:\course\course_django\djenv\lib\site-packages\colorama\ansitowin32.py", line 196, in write_plain_text
    self.wrapped.flush()
OSError: [WinError 6] 句柄无效。
--- End of logging error ---
--- Logging error in Loguru Handler #0 ---
Record was: {'elapsed': datetime.timedelta(seconds=5, microseconds=760527), 'exception': None, 'extra': {}, 'file': (name='runner.py', path='d:\\course\\course_django\\djenv\\lib\\site-packages\\httprunner\\runner.py'), 'function': 'test_start', 'level': (name='INFO', no=20, icon='ℹ️'), 'line': 460, 'message': 'generate testcase log: D:\\Course\\course_django\\autotpsite\\logs\\d01fc0fc-0d37-49a3-8434-dc6a2bc15ff2.run.log', 'module': 'runner', 'name': 'httprunner.runner', 'process': (id=20516, name='MainProcess'), 'thread': (id=24788, name='MainThread'), 'time': datetime(2021, 11, 10, 16, 54, 37, 254076, tzinfo=datetime.timezone(datetime.timedelta(seconds=28800), '中国标准时间'))}
Traceback (most recent call last):
  File "d:\course\course_django\djenv\lib\site-packages\loguru\_handler.py", line 177, in emit
    self._sink.write(str_record)
  File "d:\course\course_django\djenv\lib\site-packages\loguru\_simple_sinks.py", line 26, in write
    self._stream.write(message)
  File "d:\course\course_django\djenv\lib\site-packages\colorama\ansitowin32.py", line 41, in write
    self.__convertor.write(text)
  File "d:\course\course_django\djenv\lib\site-packages\colorama\ansitowin32.py", line 162, in write
    self.write_and_convert(text)
  File "d:\course\course_django\djenv\lib\site-packages\colorama\ansitowin32.py", line 187, in write_and_convert
    self.write_plain_text(text, cursor, start)
  File "d:\course\course_django\djenv\lib\site-packages\colorama\ansitowin32.py", line 196, in write_plain_text
    self.wrapped.flush()
OSError: [WinError 6] 句柄无效。
--- End of logging error ---
